Workbook

Sheet Documentation
A1: 📄 PROJECT DOCUMENTATION | AI Tool Usage & Productivity Dashboard
A3: PROJECT OVERVIEW
A4: Project Title | B4: AI Tool Usage & Productivity Dashboard – 2024/2025
A5: Objective | B5: Analyse AI tool adoption, usage patterns, and productivity impact across roles and departments
A6: Dataset Size | B6: 200 records × 20 columns | 15 months (Jan 2024 – Mar 2025)
A7: AI Tools Covered | B7: ChatGPT, Gemini, Copilot, Claude, Perplexity
A8: User Roles | B8: Student, Employee, Freelancer, Researcher, Manager
A9: Geography | B9: 8 Indian cities | Urban & Semi-Urban classification
A10: Tools Used | B10: Microsoft Excel (No VBA / Macros / Power Query)
A12: SHEET STRUCTURE
A13: Raw_Data | B13: 200-row master dataset with all 20 columns including auto-calculated Performance Category & Status
A14: Data_Cleaning | B14: 10-step data quality checklist with formulas, issues found, and resolutions
A15: Analysis | B15: 4 analysis tables: Tool Summary, Role Analysis, Monthly Trend, Urban vs Semi-Urban
A16: Pivot_Summary | B16: 3 pivot-style crosstab tables powering charts and dashboard slicers
A17: Charts | B17: 4 embedded charts: Bar, Pie, Line, Grouped Bar with formatted series
A18: 🎯 Dashboard | B18: Executive dashboard with 6 KPI cards, 5 summary tables, insights, and footer
A19: Documentation | B19: This sheet – full project documentation for portfolio use
A21: FORMULAS USED
A22: IF / Nested IF | B22: =IF(L2>=90,"Top Performer",IF(L2>=75,"High Performer",IF(L2>=60,"Average","Needs Improvement"))) -> Needs Improvement
A23: COUNTIF | B23: ChatGPT has the highest adoption rate (~21% market share) across all roles
A24: COUNTIFS | B24: Average daily AI usage is 2.8 hrs; employees save ~2.1 hrs/day using AI tools
A25: SUMIF | B25: Enterprise plan users score 23% higher productivity than Free-tier users
A26: AVERAGEIF | B26: Researchers record the highest average productivity score (82.4)
A27: AVERAGEIFS | B27: Urban users adopt AI faster but Semi-Urban growth rate is accelerating Q3→Q4 2024
A28: MAXIFS | B28: Error reduction averages 27% across all tools – Copilot leads in Engineering tasks
A29: INDEX-MATCH | B29: Top Performers (score ≥90) represent ~18% of total users – prime upsell candidates
A30: VLOOKUP equiv. | B30: Used INDEX-MATCH for two-way lookup in Pivot Summary tables
A31: Colour Scale CF | B31: Conditional Formatting on Productivity Score: Red→Yellow→Green
A32: Data Validation | B32: Satisfaction Rating locked to decimal 1-5 with error alert
A34: KEY INSIGHTS
A35: Insight 1 | B35: ChatGPT has the highest adoption rate (~21% market share) across all roles
A36: Insight 2 | B36: Average daily AI usage is 2.8 hrs; employees save ~2.1 hrs/day using AI tools
A37: Insight 3 | B37: Enterprise plan users score 23% higher productivity than Free-tier users
A38: Insight 4 | B38: Researchers record the highest average productivity score (82.4)
A39: Insight 5 | B39: Urban users adopt AI faster but Semi-Urban growth rate is accelerating Q3→Q4 2024
A40: Insight 6 | B40: Error reduction averages 27% across all tools – Copilot leads in Engineering tasks
A41: Insight 7 | B41: Top Performers (score ≥90) represent ~18% of total users – prime upsell candidates
A43: RESUME DESCRIPTION
A44: One-liner | B44: Built an interactive Excel dashboard analysing AI tool adoption across 200 users, 5 tools, and 15 months
A45: Bullet 1 | B45: • Cleaned and validated 200-row dataset using 10-step quality checks (deduplication, range validation, standardisation)
...

Sheet Charts
A1: 📈 EMBEDDED CHARTS
A3: Chart 1: Avg Productivity Score by AI Tool | N3: Chart 2: AI Tool Market Share
A4: AI Tool | B4: Avg Productivity | N4: AI Tool | O4: User Count
A5: ChatGPT | B5: =AVERAGEIF(Raw_Data!I$2:I$201,A5,Raw_Data!L$2:L$201) -> 74.186486 | N5: ChatGPT | O5: =COUNTIF(Raw_Data!I$2:I$201,N5) -> 37
A6: Gemini | B6: =AVERAGEIF(Raw_Data!I$2:I$201,A6,Raw_Data!L$2:L$201) -> 74.584615 | N6: Gemini | O6: =COUNTIF(Raw_Data!I$2:I$201,N6) -> 39
A7: Copilot | B7: =AVERAGEIF(Raw_Data!I$2:I$201,A7,Raw_Data!L$2:L$201) -> 77.3175 | N7: Copilot | O7: =COUNTIF(Raw_Data!I$2:I$201,N7) -> 40
A8: Claude | B8: =AVERAGEIF(Raw_Data!I$2:I$201,A8,Raw_Data!L$2:L$201) -> 75.077083 | N8: Claude | O8: =COUNTIF(Raw_Data!I$2:I$201,N8) -> 48
A9: Perplexity | B9: =AVERAGEIF(Raw_Data!I$2:I$201,A9,Raw_Data!L$2:L$201) -> 78.291667 | N9: Perplexity | O9: =COUNTIF(Raw_Data!I$2:I$201,N9) -> 36
A20: Chart 3: Monthly User Growth Trend | N20: Chart 4: Role-Based Productivity
A21: Month | B21: Users | C21: Avg Prod | N21: Role | O21: Avg Productivity | P21: Avg Time Saved
A22: Jan-24 | B22: =COUNTIF(Raw_Data!B$2:B$201,A22) -> 8 | C22: =AVERAGEIF(Raw_Data!B$2:B$201,A22,Raw_Data!L$2:L$201) -> 78.95 | N22: Student | O22: =AVERAGEIF(Raw_Data!D$2:D$201,N22,Raw_Data!L$2:L$201) -> 75.386957 | P22: =AVERAGEIF(Raw_Data!D$2:D$201,N22,Raw_Data!M$2:M$201) -> 1.8695652
A23: Feb-24 | B23: =COUNTIF(Raw_Data!B$2:B$201,A23) -> 17 | C23: =AVERAGEIF(Raw_Data!B$2:B$201,A23,Raw_Data!L$2:L$201) -> 74.117647 | N23: Employee | O23: =AVERAGEIF(Raw_Data!D$2:D$201,N23,Raw_Data!L$2:L$201) -> 73.57 | P23: =AVERAGEIF(Raw_Data!D$2:D$201,N23,Raw_Data!M$2:M$201) -> 1.87
A24: Mar-24 | B24: =COUNTIF(Raw_Data!B$2:B$201,A24) -> 15 | C24: =AVERAGEIF(Raw_Data!B$2:B$201,A24,Raw_Data!L$2:L$201) -> 75.26 | N24: Freelancer | O24: =AVERAGEIF(Raw_Data!D$2:D$201,N24,Raw_Data!L$2:L$201) -> 75.219444 | P24: =AVERAGEIF(Raw_Data!D$2:D$201,N24,Raw_Data!M$2:M$201) -> 2.0166667
A25: Apr-24 | B25: =COUNTIF(Raw_Data!B$2:B$201,A25) -> 13 | C25: =AVERAGEIF(Raw_Data!B$2:B$201,A25,Raw_Data!L$2:L$201) -> 79.792308 | N25: Researcher | O25: =AVERAGEIF(Raw_Data!D$2:D$201,N25,Raw_Data!L$2:L$201) -> 76.37027 | P25: =AVERAGEIF(Raw_Data!D$2:D$201,N25,Raw_Data!M$2:M$201) -> 2.0405405
A26: May-24 | B26: =COUNTIF(Raw_Data!B$2:B$201,A26) -> 11 | C26: =AVERAGEIF(Raw_Data!B$2:B$201,A26,Raw_Data!L$2:L$201) -> 76.118182 | N26: Manager | O26: =AVERAGEIF(Raw_Data!D$2:D$201,N26,Raw_Data!L$2:L$201) -> 78.643902 | P26: =AVERAGEIF(Raw_Data!D$2:D$201,N26,Raw_Data!M$2:M$201) -> 1.7853659
A27: Jun-24 | B27: =COUNTIF(Raw_Data!B$2:B$201,A27) -> 13 | C27: =AVERAGEIF(Raw_Data!B$2:B$201,A27,Raw_Data!L$2:L$201) -> 70.053846
A28: Jul-24 | B28: =COUNTIF(Raw_Data!B$2:B$201,A28) -> 13 | C28: =AVERAGEIF(Raw_Data!B$2:B$201,A28,Raw_Data!L$2:L$201) -> 75.546154
A29: Aug-24 | B29: =COUNTIF(Raw_Data!B$2:B$201,A29) -> 13 | C29: =AVERAGEIF(Raw_Data!B$2:B$201,A29,Raw_Data!L$2:L$201) -> 74.115385
A30: Sep-24 | B30: =COUNTIF(Raw_Data!B$2:B$201,A30) -> 16 | C30: =AVERAGEIF(Raw_Data!B$2:B$201,A30,Raw_Data!L$2:L$201) -> 80.30625
A31: Oct-24 | B31: =COUNTIF(Raw_Data!B$2:B$201,A31) -> 21 | C31: =AVERAGEIF(Raw_Data!B$2:B$201,A31,Raw_Data!L$2:L$201) -> 73.485714
A32: Nov-24 | B32: =COUNTIF(Raw_Data!B$2:B$201,A32) -> 14 | C32: =AVERAGEIF(Raw_Data!B$2:B$201,A32,Raw_Data!L$2:L$201) -> 76.257143
A33: Dec-24 | B33: =COUNTIF(Raw_Data!B$2:B$201,A33) -> 10 | C33: =AVERAGEIF(Raw_Data!B$2:B$201,A33,Raw_Data!L$2:L$201) -> 72.31
A34: Jan-25 | B34: =COUNTIF(Raw_Data!B$2:B$201,A34) -> 9 | C34: =AVERAGEIF(Raw_Data!B$2:B$201,A34,Raw_Data!L$2:L$201) -> 77.988889
A35: Feb-25 | B35: =COUNTIF(Raw_Data!B$2:B$201,A35) -> 14 | C35: =AVERAGEIF(Raw_Data!B$2:B$201,A35,Raw_Data!L$2:L$201) -> 78.135714
A36: Mar-25 | B36: =COUNTIF(Raw_Data!B$2:B$201,A36) -> 13 | C36: =AVERAGEIF(Raw_Data!B$2:B$201,A36,Raw_Data!L$2:L$201) -> 77.123077

Sheet Pivot_Summary
A1: 📋 PIVOT SUMMARY TABLES (Source for Charts & Dashboard)
A3: PIVOT A – Avg Productivity Score by Tool & Role
A4: AI Tool | B4: Student | C4: Employee | D4: Freelancer | E4: Researcher | F4: Manager
A5: ChatGPT | B5: =AVERAGEIFS(Raw_Data!L$2:L$201,Raw_Data!I$2:I$201,A5,Raw_Data!D$2:D$201,B$4) -> 72.6 | C5: =AVERAGEIFS(Raw_Data!L$2:L$201,Raw_Data!I$2:I$201,A5,Raw_Data!D$2:D$201,C$4) -> 73.733333 | D5: =AVERAGEIFS(Raw_Data!L$2:L$201,Raw_Data!I$2:I$201,A5,Raw_Data!D$2:D$201,D$4) -> 76.483333 | E5: =AVERAGEIFS(Raw_Data!L$2:L$201,Raw_Data!I$2:I$201,A5,Raw_Data!D$2:D$201,E$4) -> 76.2 | F5: =AVERAGEIFS(Raw_Data!L$2:L$201,Raw_Data!I$2:I$201,A5,Raw_Data!D$2:D$201,F$4) -> 72.571429
A6: Gemini | B6: =AVERAGEIFS(Raw_Data!L$2:L$201,Raw_Data!I$2:I$201,A6,Raw_Data!D$2:D$201,B$4) -> 76.383333 | C6: =AVERAGEIFS(Raw_Data!L$2:L$201,Raw_Data!I$2:I$201,A6,Raw_Data!D$2:D$201,C$4) -> 71.866667 | D6: =AVERAGEIFS(Raw_Data!L$2:L$201,Raw_Data!I$2:I$201,A6,Raw_Data!D$2:D$201,D$4) -> 73.6 | E6: =AVERAGEIFS(Raw_Data!L$2:L$201,Raw_Data!I$2:I$201,A6,Raw_Data!D$2:D$201,E$4) -> 70.108333 | F6: =AVERAGEIFS(Raw_Data!L$2:L$201,Raw_Data!I$2:I$201,A6,Raw_Data!D$2:D$201,F$4) -> 81.822222
A7: Copilot | B7: =AVERAGEIFS(Raw_Data!L$2:L$201,Raw_Data!I$2:I$201,A7,Raw_Data!D$2:D$201,B$4) -> 79.616667 | C7: =AVERAGEIFS(Raw_Data!L$2:L$201,Raw_Data!I$2:I$201,A7,Raw_Data!D$2:D$201,C$4) -> 67.32 | D7: =AVERAGEIFS(Raw_Data!L$2:L$201,Raw_Data!I$2:I$201,A7,Raw_Data!D$2:D$201,D$4) -> 76.125 | E7: =AVERAGEIFS(Raw_Data!L$2:L$201,Raw_Data!I$2:I$201,A7,Raw_Data!D$2:D$201,E$4) -> 76.575 | F7: =AVERAGEIFS(Raw_Data!L$2:L$201,Raw_Data!I$2:I$201,A7,Raw_Data!D$2:D$201,F$4) -> 80.490909
A8: Claude | B8: =AVERAGEIFS(Raw_Data!L$2:L$201,Raw_Data!I$2:I$201,A8,Raw_Data!D$2:D$201,B$4) -> 67.275 | C8: =AVERAGEIFS(Raw_Data!L$2:L$201,Raw_Data!I$2:I$201,A8,Raw_Data!D$2:D$201,C$4) -> 73.316667 | D8: =AVERAGEIFS(Raw_Data!L$2:L$201,Raw_Data!I$2:I$201,A8,Raw_Data!D$2:D$201,D$4) -> 74.272727 | E8: =AVERAGEIFS(Raw_Data!L$2:L$201,Raw_Data!I$2:I$201,A8,Raw_Data!D$2:D$201,E$4) -> 85.316667 | F8: =AVERAGEIFS(Raw_Data!L$2:L$201,Raw_Data!I$2:I$201,A8,Raw_Data!D$2:D$201,F$4) -> 77.890909
A9: Perplexity | B9: =AVERAGEIFS(Raw_Data!L$2:L$201,Raw_Data!I$2:I$201,A9,Raw_Data!D$2:D$201,B$4) -> 78.99 | C9: =AVERAGEIFS(Raw_Data!L$2:L$201,Raw_Data!I$2:I$201,A9,Raw_Data!D$2:D$201,C$4) -> 77.527273 | D9: =AVERAGEIFS(Raw_Data!L$2:L$201,Raw_Data!I$2:I$201,A9,Raw_Data!D$2:D$201,D$4) -> 76.28 | E9: =AVERAGEIFS(Raw_Data!L$2:L$201,Raw_Data!I$2:I$201,A9,Raw_Data!D$2:D$201,E$4) -> 79.514286 | F9: =AVERAGEIFS(Raw_Data!L$2:L$201,Raw_Data!I$2:I$201,A9,Raw_Data!D$2:D$201,F$4) -> 79.266667
A11: PIVOT B – Monthly User Count by AI Tool
A12: AI Tool | B12: Jan-24 | C12: Feb-24 | D12: Mar-24 | E12: Apr-24 | F12: May-24 | G12: Jun-24 | H12: Jul-24 | I12: Aug-24 | J12: Sep-24 | K12: Oct-24 | L12: Nov-24 | M12: Dec-24 | N12: Jan-25 | O12: Feb-25 | P12: Mar-25
A13: ChatGPT | B13: =COUNTIFS(Raw_Data!I$2:I$201,A13,Raw_Data!B$2:B$201,B$12) -> 4 | C13: =COUNTIFS(Raw_Data!I$2:I$201,A13,Raw_Data!B$2:B$201,C$12) -> 3 | D13: =COUNTIFS(Raw_Data!I$2:I$201,A13,Raw_Data!B$2:B$201,D$12) -> 3 | E13: =COUNTIFS(Raw_Data!I$2:I$201,A13,Raw_Data!B$2:B$201,E$12) -> 4 | F13: =COUNTIFS(Raw_Data!I$2:I$201,A13,Raw_Data!B$2:B$201,F$12) -> 2 | G13: =COUNTIFS(Raw_Data!I$2:I$201,A13,Raw_Data!B$2:B$201,G$12) -> 0 | H13: =COUNTIFS(Raw_Data!I$2:I$201,A13,Raw_Data!B$2:B$201,H$12) -> 1 | I13: =COUNTIFS(Raw_Data!I$2:I$201,A13,Raw_Data!B$2:B$201,I$12) -> 2 | J13: =COUNTIFS(Raw_Data!I$2:I$201,A13,Raw_Data!B$2:B$201,J$12) -> 1 | K13: =COUNTIFS(Raw_Data!I$2:I$201,A13,Raw_Data!B$2:B$201,K$12) -> 3 | L13: =COUNTIFS(Raw_Data!I$2:I$201,A13,Raw_Data!B$2:B$201,L$12) -> 2 | M13: =COUNTIFS(Raw_Data!I$2:I$201,A13,Raw_Data!B$2:B$201,M$12) -> 2 | N13: =COUNTIFS(Raw_Data!I$2:I$201,A13,Raw_Data!B$2:B$201,N$12) -> 1 | O13: =COUNTIFS(Raw_Data!I$2:I$201,A13,Raw_Data!B$2:B$201,O$12) -> 5 | P13: =COUNTIFS(Raw_Data!I$2:I$201,A13,Raw_Data!B$2:B$201,P$12) -> 4
A14: Gemini | B14: =COUNTIFS(Raw_Data!I$2:I$201,A14,Raw_Data!B$2:B$201,B$12) -> 1 | C14: =COUNTIFS(Raw_Data!I$2:I$201,A14,Raw_Data!B$2:B$201,C$12) -> 3 | D14: =COUNTIFS(Raw_Data!I$2:I$201,A14,Raw_Data!B$2:B$201,D$12) -> 4 | E14: =COUNTIFS(Raw_Data!I$2:I$201,A14,Raw_Data!B$2:B$201,E$12) -> 0 | F14: =COUNTIFS(Raw_Data!I$2:I$201,A14,Raw_Data!B$2:B$201,F$12) -> 4 | G14: =COUNTIFS(Raw_Data!I$2:I$201,A14,Raw_Data!B$2:B$201,G$12) -> 1 | H14: =COUNTIFS(Raw_Data!I$2:I$201,A14,Raw_Data!B$2:B$201,H$12) -> 3 | I14: =COUNTIFS(Raw_Data!I$2:I$201,A14,Raw_Data!B$2:B$201,I$12) -> 2 | J14: =COUNTIFS(Raw_Data!I$2:I$201,A14,Raw_Data!B$2:B$201,J$12) -> 2 | K14: =COUNTIFS(Raw_Data!I$2:I$201,A14,Raw_Data!B$2:B$201,K$12) -> 5 | L14: =COUNTIFS(Raw_Data!I$2:I$201,A14,Raw_Data!B$2:B$201,L$12) -> 4 | M14: =COUNTIFS(Raw_Data!I$2:I$201,A14,Raw_Data!B$2:B$201,M$12) -> 1 | N14: =COUNTIFS(Raw_Data!I$2:I$201,A14,Raw_Data!B$2:B$201,N$12) -> 2 | O14: =COUNTIFS(Raw_Data!I$2:I$201,A14,Raw_Data!B$2:B$201,O$12) -> 6 | P14: =COUNTIFS(Raw_Data!I$2:I$201,A14,Raw_Data!B$2:B$201,P$12) -> 1
A15: Copilot | B15: =COUNTIFS(Raw_Data!I$2:I$201,A15,Raw_Data!B$2:B$201,B$12) -> 1 | C15: =COUNTIFS(Raw_Data!I$2:I$201,A15,Raw_Data!B$2:B$201,C$12) -> 3 | D15: =COUNTIFS(Raw_Data!I$2:I$201,A15,Raw_Data!B$2:B$201,D$12) -> 6 | E15: =COUNTIFS(Raw_Data!I$2:I$201,A15,Raw_Data!B$2:B$201,E$12) -> 2 | F15: =COUNTIFS(Raw_Data!I$2:I$201,A15,Raw_Data!B$2:B$201,F$12) -> 2 | G15: =COUNTIFS(Raw_Data!I$2:I$201,A15,Raw_Data!B$2:B$201,G$12) -> 3 | H15: =COUNTIFS(Raw_Data!I$2:I$201,A15,Raw_Data!B$2:B$201,H$12) -> 1 | I15: =COUNTIFS(Raw_Data!I$2:I$201,A15,Raw_Data!B$2:B$201,I$12) -> 3 | J15: =COUNTIFS(Raw_Data!I$2:I$201,A15,Raw_Data!B$2:B$201,J$12) -> 4 | K15: =COUNTIFS(Raw_Data!I$2:I$201,A15,Raw_Data!B$2:B$201,K$12) -> 5 | L15: =COUNTIFS(Raw_Data!I$2:I$201,A15,Raw_Data!B$2:B$201,L$12) -> 3 | M15: =COUNTIFS(Raw_Data!I$2:I$201,A15,Raw_Data!B$2:B$201,M$12) -> 2 | N15: =COUNTIFS(Raw_Data!I$2:I$201,A15,Raw_Data!B$2:B$201,N$12) -> 3 | O15: =COUNTIFS(Raw_Data!I$2:I$201,A15,Raw_Data!B$2:B$201,O$12) -> 0 | P15: =COUNTIFS(Raw_Data!I$2:I$201,A15,Raw_Data!B$2:B$201,P$12) -> 2
A16: Claude | B16: =COUNTIFS(Raw_Data!I$2:I$201,A16,Raw_Data!B$2:B$201,B$12) -> 1 | C16: =COUNTIFS(Raw_Data!I$2:I$201,A16,Raw_Data!B$2:B$201,C$12) -> 3 | D16: =COUNTIFS(Raw_Data!I$2:I$201,A16,Raw_Data!B$2:B$201,D$12) -> 2 | E16: =COUNTIFS(Raw_Data!I$2:I$201,A16,Raw_Data!B$2:B$201,E$12) -> 2 | F16: =COUNTIFS(Raw_Data!I$2:I$201,A16,Raw_Data!B$2:B$201,F$12) -> 2 | G16: =COUNTIFS(Raw_Data!I$2:I$201,A16,Raw_Data!B$2:B$201,G$12) -> 6 | H16: =COUNTIFS(Raw_Data!I$2:I$201,A16,Raw_Data!B$2:B$201,H$12) -> 7 | I16: =COUNTIFS(Raw_Data!I$2:I$201,A16,Raw_Data!B$2:B$201,I$12) -> 2 | J16: =COUNTIFS(Raw_Data!I$2:I$201,A16,Raw_Data!B$2:B$201,J$12) -> 6 | K16: =COUNTIFS(Raw_Data!I$2:I$201,A16,Raw_Data!B$2:B$201,K$12) -> 5 | L16: =COUNTIFS(Raw_Data!I$2:I$201,A16,Raw_Data!B$2:B$201,L$12) -> 2 | M16: =COUNTIFS(Raw_Data!I$2:I$201,A16,Raw_Data!B$2:B$201,M$12) -> 4 | N16: =COUNTIFS(Raw_Data!I$2:I$201,A16,Raw_Data!B$2:B$201,N$12) -> 3 | O16: =COUNTIFS(Raw_Data!I$2:I$201,A16,Raw_Data!B$2:B$201,O$12) -> 0 | P16: =COUNTIFS(Raw_Data!I$2:I$201,A16,Raw_Data!B$2:B$201,P$12) -> 3
A17: Perplexity | B17: =COUNTIFS(Raw_Data!I$2:I$201,A17,Raw_Data!B$2:B$201,B$12) -> 1 | C17: =COUNTIFS(Raw_Data!I$2:I$201,A17,Raw_Data!B$2:B$201,C$12) -> 5 | D17: =COUNTIFS(Raw_Data!I$2:I$201,A17,Raw_Data!B$2:B$201,D$12) -> 0 | E17: =COUNTIFS(Raw_Data!I$2:I$201,A17,Raw_Data!B$2:B$201,E$12) -> 5 | F17: =COUNTIFS(Raw_Data!I$2:I$201,A17,Raw_Data!B$2:B$201,F$12) -> 1 | G17: =COUNTIFS(Raw_Data!I$2:I$201,A17,Raw_Data!B$2:B$201,G$12) -> 3 | H17: =COUNTIFS(Raw_Data!I$2:I$201,A17,Raw_Data!B$2:B$201,H$12) -> 1 | I17: =COUNTIFS(Raw_Data!I$2:I$201,A17,Raw_Data!B$2:B$201,I$12) -> 4 | J17: =COUNTIFS(Raw_Data!I$2:I$201,A17,Raw_Data!B$2:B$201,J$12) -> 3 | K17: =COUNTIFS(Raw_Data!I$2:I$201,A17,Raw_Data!B$2:B$201,K$12) -> 3 | L17: =COUNTIFS(Raw_Data!I$2:I$201,A17,Raw_Data!B$2:B$201,L$12) -> 3 | M17: =COUNTIFS(Raw_Data!I$2:I$201,A17,Raw_Data!B$2:B$201,M$12) -> 1 | N17: =COUNTIFS(Raw_Data!I$2:I$201,A17,Raw_Data!B$2:B$201,N$12) -> 0 | O17: =COUNTIFS(Raw_Data!I$2:I$201,A17,Raw_Data!B$2:B$201,O$12) -> 3 | P17: =COUNTIFS(Raw_Data!I$2:I$201,A17,Raw_Data!B$2:B$201,P$12) -> 3
A20: PIVOT C – Subscription Type Distribution
A21: AI Tool | B21: Free Users | C21: Pro Users | D21: Enterprise Users | E21: Total
A22: ChatGPT | B22: =COUNTIFS(Raw_Data!I$2:I$201,A22,Raw_Data!O$2:O$201,"Free") -> 15 | C22: =COUNTIFS(Raw_Data!I$2:I$201,A22,Raw_Data!O$2:O$201,"Pro") -> 11 | D22: =COUNTIFS(Raw_Data!I$2:I$201,A22,Raw_Data!O$2:O$201,"Enterprise") -> 11 | E22: =SUM(B22:D22) -> 37
A23: Gemini | B23: =COUNTIFS(Raw_Data!I$2:I$201,A23,Raw_Data!O$2:O$201,"Free") -> 8 | C23: =COUNTIFS(Raw_Data!I$2:I$201,A23,Raw_Data!O$2:O$201,"Pro") -> 15 | D23: =COUNTIFS(Raw_Data!I$2:I$201,A23,Raw_Data!O$2:O$201,"Enterprise") -> 16 | E23: =SUM(B23:D23) -> 39
A24: Copilot | B24: =COUNTIFS(Raw_Data!I$2:I$201,A24,Raw_Data!O$2:O$201,"Free") -> 15 | C24: =COUNTIFS(Raw_Data!I$2:I$201,A24,Raw_Data!O$2:O$201,"Pro") -> 12 | D24: =COUNTIFS(Raw_Data!I$2:I$201,A24,Raw_Data!O$2:O$201,"Enterprise") -> 13 | E24: =SUM(B24:D24) -> 40
A25: Claude | B25: =COUNTIFS(Raw_Data!I$2:I$201,A25,Raw_Data!O$2:O$201,"Free") -> 16 | C25: =COUNTIFS(Raw_Data!I$2:I$201,A25,Raw_Data!O$2:O$201,"Pro") -> 19 | D25: =COUNTIFS(Raw_Data!I$2:I$201,A25,Raw_Data!O$2:O$201,"Enterprise") -> 13 | E25: =SUM(B25:D25) -> 48
A26: Perplexity | B26: =COUNTIFS(Raw_Data!I$2:I$201,A26,Raw_Data!O$2:O$201,"Free") -> 11 | C26: =COUNTIFS(Raw_Data!I$2:I$201,A26,Raw_Data!O$2:O$201,"Pro") -> 11 | D26: =COUNTIFS(Raw_Data!I$2:I$201,A26,Raw_Data!O$2:O$201,"Enterprise") -> 14 | E26: =SUM(B26:D26) -> 36

Sheet Analysis
A1: 📊 FORMULA-BASED ANALYSIS & KPI CALCULATIONS
A3: A. AI Tool Performance Summary
A4: AI Tool | B4: Total Users | C4: Avg Daily Usage (Hrs) | D4: Avg Productivity Score | E4: Avg Time Saved (Hrs) | F4: Avg Satisfaction | G4: Avg Tasks Completed | H4: Avg Error Reduction % | I4: Market Share %
A5: ChatGPT | B5: =COUNTIF(Raw_Data!I$2:I$201,A5) -> 37 | C5: =AVERAGEIF(Raw_Data!I$2:I$201,A5,Raw_Data!J$2:J$201) -> 3.1891892 | D5: =AVERAGEIF(Raw_Data!I$2:I$201,A5,Raw_Data!L$2:L$201) -> 74.186486 | E5: =AVERAGEIF(Raw_Data!I$2:I$201,A5,Raw_Data!M$2:M$201) -> 1.9216216 | F5: =AVERAGEIF(Raw_Data!I$2:I$201,A5,Raw_Data!N$2:N$201) -> 4.0135135 | G5: =AVERAGEIF(Raw_Data!I$2:I$201,A5,Raw_Data!K$2:K$201) -> 22.891892 | H5: =AVERAGEIF(Raw_Data!I$2:I$201,A5,Raw_Data!Q$2:Q$201) -> 28.559459 | I5: =B5/SUM(B$5:B$9) -> 0.185
A6: Gemini | B6: =COUNTIF(Raw_Data!I$2:I$201,A6) -> 39 | C6: =AVERAGEIF(Raw_Data!I$2:I$201,A6,Raw_Data!J$2:J$201) -> 3.4307692 | D6: =AVERAGEIF(Raw_Data!I$2:I$201,A6,Raw_Data!L$2:L$201) -> 74.584615 | E6: =AVERAGEIF(Raw_Data!I$2:I$201,A6,Raw_Data!M$2:M$201) -> 1.8871795 | F6: =AVERAGEIF(Raw_Data!I$2:I$201,A6,Raw_Data!N$2:N$201) -> 4.0076923 | G6: =AVERAGEIF(Raw_Data!I$2:I$201,A6,Raw_Data!K$2:K$201) -> 22.128205 | H6: =AVERAGEIF(Raw_Data!I$2:I$201,A6,Raw_Data!Q$2:Q$201) -> 28.641026 | I6: =B6/SUM(B$5:B$9) -> 0.195
A7: Copilot | B7: =COUNTIF(Raw_Data!I$2:I$201,A7) -> 40 | C7: =AVERAGEIF(Raw_Data!I$2:I$201,A7,Raw_Data!J$2:J$201) -> 3.23 | D7: =AVERAGEIF(Raw_Data!I$2:I$201,A7,Raw_Data!L$2:L$201) -> 77.3175 | E7: =AVERAGEIF(Raw_Data!I$2:I$201,A7,Raw_Data!M$2:M$201) -> 1.8675 | F7: =AVERAGEIF(Raw_Data!I$2:I$201,A7,Raw_Data!N$2:N$201) -> 4.0875 | G7: =AVERAGEIF(Raw_Data!I$2:I$201,A7,Raw_Data!K$2:K$201) -> 21.95 | H7: =AVERAGEIF(Raw_Data!I$2:I$201,A7,Raw_Data!Q$2:Q$201) -> 28.7025 | I7: =B7/SUM(B$5:B$9) -> 0.2
A8: Claude | B8: =COUNTIF(Raw_Data!I$2:I$201,A8) -> 48 | C8: =AVERAGEIF(Raw_Data!I$2:I$201,A8,Raw_Data!J$2:J$201) -> 3.05625 | D8: =AVERAGEIF(Raw_Data!I$2:I$201,A8,Raw_Data!L$2:L$201) -> 75.077083 | E8: =AVERAGEIF(Raw_Data!I$2:I$201,A8,Raw_Data!M$2:M$201) -> 1.86875 | F8: =AVERAGEIF(Raw_Data!I$2:I$201,A8,Raw_Data!N$2:N$201) -> 4.0354167 | G8: =AVERAGEIF(Raw_Data!I$2:I$201,A8,Raw_Data!K$2:K$201) -> 22.458333 | H8: =AVERAGEIF(Raw_Data!I$2:I$201,A8,Raw_Data!Q$2:Q$201) -> 27.09375 | I8: =B8/SUM(B$5:B$9) -> 0.24
A9: Perplexity | B9: =COUNTIF(Raw_Data!I$2:I$201,A9) -> 36 | C9: =AVERAGEIF(Raw_Data!I$2:I$201,A9,Raw_Data!J$2:J$201) -> 3.3916667 | D9: =AVERAGEIF(Raw_Data!I$2:I$201,A9,Raw_Data!L$2:L$201) -> 78.291667 | E9: =AVERAGEIF(Raw_Data!I$2:I$201,A9,Raw_Data!M$2:M$201) -> 2.0277778 | F9: =AVERAGEIF(Raw_Data!I$2:I$201,A9,Raw_Data!N$2:N$201) -> 4.0361111 | G9: =AVERAGEIF(Raw_Data!I$2:I$201,A9,Raw_Data!K$2:K$201) -> 22.75 | H9: =AVERAGEIF(Raw_Data!I$2:I$201,A9,Raw_Data!Q$2:Q$201) -> 26.577778 | I9: =B9/SUM(B$5:B$9) -> 0.18
A10: TOTAL / AVG | B10: =SUM(B5:B9) -> 200 | C10: =AVERAGE(C5:C9) -> 3.259575 | D10: =AVERAGE(D5:D9) -> 75.89147 | E10: =AVERAGE(E5:E9) -> 1.9145658 | F10: =AVERAGE(F5:F9) -> 4.0360467 | G10: =AVERAGE(G5:G9) -> 22.435686 | H10: =AVERAGE(H5:H9) -> 27.914903 | I10: =SUM(I5:I9) -> 1
A12: B. Role-Based Productivity Analysis
A13: Role | B13: Count | C13: Avg Productivity | D13: Avg Time Saved | E13: Avg Satisfaction | F13: Top AI Tool | G13: Avg Tasks | H13: High Performers | I13: High Performer %
A14: Student | B14: =COUNTIF(Raw_Data!D$2:D$201,A14) -> 46 | C14: =AVERAGEIF(Raw_Data!D$2:D$201,A14,Raw_Data!L$2:L$201) -> 75.386957 | D14: =AVERAGEIF(Raw_Data!D$2:D$201,A14,Raw_Data!M$2:M$201) -> 1.8695652 | E14: =AVERAGEIF(Raw_Data!D$2:D$201,A14,Raw_Data!N$2:N$201) -> 4.0956522 | F14: =IFERROR(INDEX(Raw_Data!I$2:I$201,MATCH(MAX(IF(Raw_Data!D$2:D$201=A14,Raw_Data!L$2:L$201)),Raw_Data!L$2:L$201,0)),"N/A") -> N/A | G14: =AVERAGEIF(Raw_Data!D$2:D$201,A14,Raw_Data!K$2:K$201) -> 22.913043 | H14: =COUNTIFS(Raw_Data!D$2:D$201,A14,Raw_Data!S$2:S$201,"Top Performer") -> 9 | I14: =H14/B14 -> 0.19565217
A15: Employee | B15: =COUNTIF(Raw_Data!D$2:D$201,A15) -> 40 | C15: =AVERAGEIF(Raw_Data!D$2:D$201,A15,Raw_Data!L$2:L$201) -> 73.57 | D15: =AVERAGEIF(Raw_Data!D$2:D$201,A15,Raw_Data!M$2:M$201) -> 1.87 | E15: =AVERAGEIF(Raw_Data!D$2:D$201,A15,Raw_Data!N$2:N$201) -> 4.1025 | F15: =IFERROR(INDEX(Raw_Data!I$2:I$201,MATCH(MAX(IF(Raw_Data!D$2:D$201=A15,Raw_Data!L$2:L$201)),Raw_Data!L$2:L$201,0)),"N/A") -> N/A | G15: =AVERAGEIF(Raw_Data!D$2:D$201,A15,Raw_Data!K$2:K$201) -> 21.45 | H15: =COUNTIFS(Raw_Data!D$2:D$201,A15,Raw_Data!S$2:S$201,"Top Performer") -> 6 | I15: =H15/B15 -> 0.15
A16: Freelancer | B16: =COUNTIF(Raw_Data!D$2:D$201,A16) -> 36 | C16: =AVERAGEIF(Raw_Data!D$2:D$201,A16,Raw_Data!L$2:L$201) -> 75.219444 | D16: =AVERAGEIF(Raw_Data!D$2:D$201,A16,Raw_Data!M$2:M$201) -> 2.0166667 | E16: =AVERAGEIF(Raw_Data!D$2:D$201,A16,Raw_Data!N$2:N$201) -> 4.1722222 | F16: =IFERROR(INDEX(Raw_Data!I$2:I$201,MATCH(MAX(IF(Raw_Data!D$2:D$201=A16,Raw_Data!L$2:L$201)),Raw_Data!L$2:L$201,0)),"N/A") -> N/A | G16: =AVERAGEIF(Raw_Data!D$2:D$201,A16,Raw_Data!K$2:K$201) -> 23.416667 | H16: =COUNTIFS(Raw_Data!D$2:D$201,A16,Raw_Data!S$2:S$201,"Top Performer") -> 6 | I16: =H16/B16 -> 0.16666667
A17: Researcher | B17: =COUNTIF(Raw_Data!D$2:D$201,A17) -> 37 | C17: =AVERAGEIF(Raw_Data!D$2:D$201,A17,Raw_Data!L$2:L$201) -> 76.37027 | D17: =AVERAGEIF(Raw_Data!D$2:D$201,A17,Raw_Data!M$2:M$201) -> 2.0405405 | E17: =AVERAGEIF(Raw_Data!D$2:D$201,A17,Raw_Data!N$2:N$201) -> 3.9405405 | F17: =IFERROR(INDEX(Raw_Data!I$2:I$201,MATCH(MAX(IF(Raw_Data!D$2:D$201=A17,Raw_Data!L$2:L$201)),Raw_Data!L$2:L$201,0)),"N/A") -> N/A | G17: =AVERAGEIF(Raw_Data!D$2:D$201,A17,Raw_Data!K$2:K$201) -> 23.216216 | H17: =COUNTIFS(Raw_Data!D$2:D$201,A17,Raw_Data!S$2:S$201,"Top Performer") -> 4 | I17: =H17/B17 -> 0.10810811
A18: Manager | B18: =COUNTIF(Raw_Data!D$2:D$201,A18) -> 41 | C18: =AVERAGEIF(Raw_Data!D$2:D$201,A18,Raw_Data!L$2:L$201) -> 78.643902 | D18: =AVERAGEIF(Raw_Data!D$2:D$201,A18,Raw_Data!M$2:M$201) -> 1.7853659 | E18: =AVERAGEIF(Raw_Data!D$2:D$201,A18,Raw_Data!N$2:N$201) -> 3.8731707 | F18: =IFERROR(INDEX(Raw_Data!I$2:I$201,MATCH(MAX(IF(Raw_Data!D$2:D$201=A18,Raw_Data!L$2:L$201)),Raw_Data!L$2:L$201,0)),"N/A") -> N/A | G18: =AVERAGEIF(Raw_Data!D$2:D$201,A18,Raw_Data!K$2:K$201) -> 21.243902 | H18: =COUNTIFS(Raw_Data!D$2:D$201,A18,Raw_Data!S$2:S$201,"Top Performer") -> 8 | I18: =H18/B18 -> 0.19512195
A20: C. Monthly Usage Trend & Growth Rate
A21: Month | B21: Total Users | C21: Total Tasks | D21: Avg Productivity | E21: Avg Time Saved | F21: MoM Growth % | G21: Cumulative Users | H21: Avg Satisfaction | I21: Cost Efficiency
A22: Jan-24 | B22: =COUNTIF(Raw_Data!B$2:B$201,A22) -> 8 | C22: =SUMIF(Raw_Data!B$2:B$201,A22,Raw_Data!K$2:K$201) -> 245 | D22: =AVERAGEIF(Raw_Data!B$2:B$201,A22,Raw_Data!L$2:L$201) -> 78.95 | E22: =AVERAGEIF(Raw_Data!B$2:B$201,A22,Raw_Data!M$2:M$201) -> 1.9375 | F22: "N/A (Base)" | G22: =IF(ROW()=22,B22,G21+B22) -> 8 | H22: =AVERAGEIF(Raw_Data!B$2:B$201,A22,Raw_Data!N$2:N$201) -> 3.9375 | I22: =D22/IF(AVERAGEIF(Raw_Data!B$2:B$201,A22,Raw_Data!P$2:P$201)=0,1,AVERAGEIF(Raw_Data!B$2:B$201,A22,Raw_Data!P$2:P$201)) -> 4.3260274
A23: Feb-24 | B23: =COUNTIF(Raw_Data!B$2:B$201,A23) -> 17 | C23: =SUMIF(Raw_Data!B$2:B$201,A23,Raw_Data!K$2:K$201) -> 409 | D23: =AVERAGEIF(Raw_Data!B$2:B$201,A23,Raw_Data!L$2:L$201) -> 74.117647 | E23: =AVERAGEIF(Raw_Data!B$2:B$201,A23,Raw_Data!M$2:M$201) -> 1.5529412 | F23: =IF(ROW()-22=0,"N/A",(B23-B22)/IF(B22=0,1,B22)) -> 1.125 | G23: =IF(ROW()=22,B23,G22+B23) -> 25 | H23: =AVERAGEIF(Raw_Data!B$2:B$201,A23,Raw_Data!N$2:N$201) -> 4.1 | I23: =D23/IF(AVERAGEIF(Raw_Data!B$2:B$201,A23,Raw_Data!P$2:P$201)=0,1,AVERAGEIF(Raw_Data!B$2:B$201,A23,Raw_Data!P$2:P$201)) -> 2.5714286
A24: Mar-24 | B24: =COUNTIF(Raw_Data!B$2:B$201,A24) -> 15 | C24: =SUMIF(Raw_Data!B$2:B$201,A24,Raw_Data!K$2:K$201) -> 359 | D24: =AVERAGEIF(Raw_Data!B$2:B$201,A24,Raw_Data!L$2:L$201) -> 75.26 | E24: =AVERAGEIF(Raw_Data!B$2:B$201,A24,Raw_Data!M$2:M$201) -> 1.5333333 | F24: =IF(ROW()-22=0,"N/A",(B24-B23)/IF(B23=0,1,B23)) -> -0.11764706 | G24: =IF(ROW()=22,B24,G23+B24) -> 40 | H24: =AVERAGEIF(Raw_Data!B$2:B$201,A24,Raw_Data!N$2:N$201) -> 4.14 | I24: =D24/IF(AVERAGEIF(Raw_Data!B$2:B$201,A24,Raw_Data!P$2:P$201)=0,1,AVERAGEIF(Raw_Data!B$2:B$201,A24,Raw_Data!P$2:P$201)) -> 2.9170543
A25: Apr-24 | B25: =COUNTIF(Raw_Data!B$2:B$201,A25) -> 13 | C25: =SUMIF(Raw_Data!B$2:B$201,A25,Raw_Data!K$2:K$201) -> 210 | D25: =AVERAGEIF(Raw_Data!B$2:B$201,A25,Raw_Data!L$2:L$201) -> 79.792308 | E25: =AVERAGEIF(Raw_Data!B$2:B$201,A25,Raw_Data!M$2:M$201) -> 1.7307692 | F25: =IF(ROW()-22=0,"N/A",(B25-B24)/IF(B24=0,1,B24)) -> -0.13333333 | G25: =IF(ROW()=22,B25,G24+B25) -> 53 | H25: =AVERAGEIF(Raw_Data!B$2:B$201,A25,Raw_Data!N$2:N$201) -> 3.9538462 | I25: =D25/IF(AVERAGEIF(Raw_Data!B$2:B$201,A25,Raw_Data!P$2:P$201)=0,1,AVERAGEIF(Raw_Data!B$2:B$201,A25,Raw_Data!P$2:P$201)) -> 3.1243976
A26: May-24 | B26: =COUNTIF(Raw_Data!B$2:B$201,A26) -> 11 | C26: =SUMIF(Raw_Data!B$2:B$201,A26,Raw_Data!K$2:K$201) -> 224 | D26: =AVERAGEIF(Raw_Data!B$2:B$201,A26,Raw_Data!L$2:L$201) -> 76.118182 | E26: =AVERAGEIF(Raw_Data!B$2:B$201,A26,Raw_Data!M$2:M$201) -> 1.7454545 | F26: =IF(ROW()-22=0,"N/A",(B26-B25)/IF(B25=0,1,B25)) -> -0.15384615 | G26: =IF(ROW()=22,B26,G25+B26) -> 64 | H26: =AVERAGEIF(Raw_Data!B$2:B$201,A26,Raw_Data!N$2:N$201) -> 4.0272727 | I26: =D26/IF(AVERAGEIF(Raw_Data!B$2:B$201,A26,Raw_Data!P$2:P$201)=0,1,AVERAGEIF(Raw_Data!B$2:B$201,A26,Raw_Data!P$2:P$201)) -> 2.6084112
A27: Jun-24 | B27: =COUNTIF(Raw_Data!B$2:B$201,A27) -> 13 | C27: =SUMIF(Raw_Data!B$2:B$201,A27,Raw_Data!K$2:K$201) -> 299 | D27: =AVERAGEIF(Raw_Data!B$2:B$201,A27,Raw_Data!L$2:L$201) -> 70.053846 | E27: =AVERAGEIF(Raw_Data!B$2:B$201,A27,Raw_Data!M$2:M$201) -> 2.3538462 | F27: =IF(ROW()-22=0,"N/A",(B27-B26)/IF(B26=0,1,B26)) -> 0.18181818 | G27: =IF(ROW()=22,B27,G26+B27) -> 77 | H27: =AVERAGEIF(Raw_Data!B$2:B$201,A27,Raw_Data!N$2:N$201) -> 4.2461538 | I27: =D27/IF(AVERAGEIF(Raw_Data!B$2:B$201,A27,Raw_Data!P$2:P$201)=0,1,AVERAGEIF(Raw_Data!B$2:B$201,A27,Raw_Data!P$2:P$201)) -> 2.4350267
A28: Jul-24 | B28: =COUNTIF(Raw_Data!B$2:B$201,A28) -> 13 | C28: =SUMIF(Raw_Data!B$2:B$201,A28,Raw_Data!K$2:K$201) -> 321 | D28: =AVERAGEIF(Raw_Data!B$2:B$201,A28,Raw_Data!L$2:L$201) -> 75.546154 | E28: =AVERAGEIF(Raw_Data!B$2:B$201,A28,Raw_Data!M$2:M$201) -> 2.4076923 | F28: =IF(ROW()-22=0,"N/A",(B28-B27)/IF(B27=0,1,B27)) -> 0 | G28: =IF(ROW()=22,B28,G27+B28) -> 90 | H28: =AVERAGEIF(Raw_Data!B$2:B$201,A28,Raw_Data!N$2:N$201) -> 4.0923077 | I28: =D28/IF(AVERAGEIF(Raw_Data!B$2:B$201,A28,Raw_Data!P$2:P$201)=0,1,AVERAGEIF(Raw_Data!B$2:B$201,A28,Raw_Data!P$2:P$201)) -> 3.1680645
A29: Aug-24 | B29: =COUNTIF(Raw_Data!B$2:B$201,A29) -> 13 | C29: =SUMIF(Raw_Data!B$2:B$201,A29,Raw_Data!K$2:K$201) -> 345 | D29: =AVERAGEIF(Raw_Data!B$2:B$201,A29,Raw_Data!L$2:L$201) -> 74.115385 | E29: =AVERAGEIF(Raw_Data!B$2:B$201,A29,Raw_Data!M$2:M$201) -> 2.2153846 | F29: =IF(ROW()-22=0,"N/A",(B29-B28)/IF(B28=0,1,B28)) -> 0 | G29: =IF(ROW()=22,B29,G28+B29) -> 103 | H29: =AVERAGEIF(Raw_Data!B$2:B$201,A29,Raw_Data!N$2:N$201) -> 4.1692308 | I29: =D29/IF(AVERAGEIF(Raw_Data!B$2:B$201,A29,Raw_Data!P$2:P$201)=0,1,AVERAGEIF(Raw_Data!B$2:B$201,A29,Raw_Data!P$2:P$201)) -> 2.6763889
A30: Sep-24 | B30: =COUNTIF(Raw_Data!B$2:B$201,A30) -> 16 | C30: =SUMIF(Raw_Data!B$2:B$201,A30,Raw_Data!K$2:K$201) -> 359 | D30: =AVERAGEIF(Raw_Data!B$2:B$201,A30,Raw_Data!L$2:L$201) -> 80.30625 | E30: =AVERAGEIF(Raw_Data!B$2:B$201,A30,Raw_Data!M$2:M$201) -> 1.93125 | F30: =IF(ROW()-22=0,"N/A",(B30-B29)/IF(B29=0,1,B29)) -> 0.23076923 | G30: =IF(ROW()=22,B30,G29+B30) -> 119 | H30: =AVERAGEIF(Raw_Data!B$2:B$201,A30,Raw_Data!N$2:N$201) -> 3.875 | I30: =D30/IF(AVERAGEIF(Raw_Data!B$2:B$201,A30,Raw_Data!P$2:P$201)=0,1,AVERAGEIF(Raw_Data!B$2:B$201,A30,Raw_Data!P$2:P$201)) -> 3.1492647
A31: Oct-24 | B31: =COUNTIF(Raw_Data!B$2:B$201,A31) -> 21 | C31: =SUMIF(Raw_Data!B$2:B$201,A31,Raw_Data!K$2:K$201) -> 329 | D31: =AVERAGEIF(Raw_Data!B$2:B$201,A31,Raw_Data!L$2:L$201) -> 73.485714 | E31: =AVERAGEIF(Raw_Data!B$2:B$201,A31,Raw_Data!M$2:M$201) -> 1.8666667 | F31: =IF(ROW()-22=0,"N/A",(B31-B30)/IF(B30=0,1,B30)) -> 0.3125 | G31: =IF(ROW()=22,B31,G30+B31) -> 140 | H31: =AVERAGEIF(Raw_Data!B$2:B$201,A31,Raw_Data!N$2:N$201) -> 4.2571429 | I31: =D31/IF(AVERAGEIF(Raw_Data!B$2:B$201,A31,Raw_Data!P$2:P$201)=0,1,AVERAGEIF(Raw_Data!B$2:B$201,A31,Raw_Data!P$2:P$201)) -> 2.8367647
A32: Nov-24 | B32: =COUNTIF(Raw_Data!B$2:B$201,A32) -> 14 | C32: =SUMIF(Raw_Data!B$2:B$201,A32,Raw_Data!K$2:K$201) -> 266 | D32: =AVERAGEIF(Raw_Data!B$2:B$201,A32,Raw_Data!L$2:L$201) -> 76.257143 | E32: =AVERAGEIF(Raw_Data!B$2:B$201,A32,Raw_Data!M$2:M$201) -> 1.7071429 | F32: =IF(ROW()-22=0,"N/A",(B32-B31)/IF(B31=0,1,B31)) -> -0.33333333 | G32: =IF(ROW()=22,B32,G31+B32) -> 154 | H32: =AVERAGEIF(Raw_Data!B$2:B$201,A32,Raw_Data!N$2:N$201) -> 3.7928571 | I32: =D32/IF(AVERAGEIF(Raw_Data!B$2:B$201,A32,Raw_Data!P$2:P$201)=0,1,AVERAGEIF(Raw_Data!B$2:B$201,A32,Raw_Data!P$2:P$201)) -> 2.7027848
A33: Dec-24 | B33: =COUNTIF(Raw_Data!B$2:B$201,A33) -> 10 | C33: =SUMIF(Raw_Data!B$2:B$201,A33,Raw_Data!K$2:K$201) -> 226 | D33: =AVERAGEIF(Raw_Data!B$2:B$201,A33,Raw_Data!L$2:L$201) -> 72.31 | E33: =AVERAGEIF(Raw_Data!B$2:B$201,A33,Raw_Data!M$2:M$201) -> 2.12 | F33: =IF(ROW()-22=0,"N/A",(B33-B32)/IF(B32=0,1,B32)) -> -0.28571429 | G33: =IF(ROW()=22,B33,G32+B33) -> 164 | H33: =AVERAGEIF(Raw_Data!B$2:B$201,A33,Raw_Data!N$2:N$201) -> 3.81 | I33: =D33/IF(AVERAGEIF(Raw_Data!B$2:B$201,A33,Raw_Data!P$2:P$201)=0,1,AVERAGEIF(Raw_Data!B$2:B$201,A33,Raw_Data!P$2:P$201)) -> 3.7082051
A34: Jan-25 | B34: =COUNTIF(Raw_Data!B$2:B$201,A34) -> 9 | C34: =SUMIF(Raw_Data!B$2:B$201,A34,Raw_Data!K$2:K$201) -> 209 | D34: =AVERAGEIF(Raw_Data!B$2:B$201,A34,Raw_Data!L$2:L$201) -> 77.988889 | E34: =AVERAGEIF(Raw_Data!B$2:B$201,A34,Raw_Data!M$2:M$201) -> 2.0222222 | F34: =IF(ROW()-22=0,"N/A",(B34-B33)/IF(B33=0,1,B33)) -> -0.1 | G34: =IF(ROW()=22,B34,G33+B34) -> 173 | H34: =AVERAGEIF(Raw_Data!B$2:B$201,A34,Raw_Data!N$2:N$201) -> 3.9222222 | I34: =D34/IF(AVERAGEIF(Raw_Data!B$2:B$201,A34,Raw_Data!P$2:P$201)=0,1,AVERAGEIF(Raw_Data!B$2:B$201,A34,Raw_Data!P$2:P$201)) -> 5.0496403
... A36: Mar-25 | B36: =COUNTIF(Raw_Data!B$2:B$201,A36) -> 13 | C36: =SUMIF(Raw_Data!B$2:B$201,A36,Raw_Data!K$2:K$201) -> 299 | D36: =AVERAGEIF(Raw_Data!B$2:B$201,A36,Raw_Data!L$2:L$201) -> 77.123077 | E36: =AVERAGEIF(Raw_Data!B$2:B$201,A36,Raw_Data!M$2:M$201) -> 1.8615385 | F36: =IF(ROW()-22=0,"N/A",(B36-B35)/IF(B35=0,1,B35)) -> -0.071428571 | G36: =IF(ROW()=22,B36,G35+B36) -> 200 | H36: =AVERAGEIF(Raw_Data!B$2:B$201,A36,Raw_Data!N$2:N$201) -> 3.8923077 | I36: =D36/IF(AVERAGEIF(Raw_Data!B$2:B$201,A36,Raw_Data!P$2:P$201)=0,1,AVERAGEIF(Raw_Data!B$2:B$201,A36,Raw_Data!P$2:P$201)) -> 4.6632558
A38: D. Urban vs Semi-Urban Productivity Comparison
A39: Location Type | B39: Count | C39: Avg Productivity | D39: Avg Time Saved | E39: Avg Daily Usage | F39: Avg Tasks | G39: Avg Satisfaction | H39: Top Tool | I39: Avg Error Reduction
A40: Urban | B40: =COUNTIF(Raw_Data!H$2:H$201,A40) -> 176 | C40: =AVERAGEIF(Raw_Data!H$2:H$201,A40,Raw_Data!L$2:L$201) -> 75.489205 | D40: =AVERAGEIF(Raw_Data!H$2:H$201,A40,Raw_Data!M$2:M$201) -> 1.9460227 | E40: =AVERAGEIF(Raw_Data!H$2:H$201,A40,Raw_Data!J$2:J$201) -> 3.3142045 | F40: =AVERAGEIF(Raw_Data!H$2:H$201,A40,Raw_Data!K$2:K$201) -> 22.261364 | G40: =AVERAGEIF(Raw_Data!H$2:H$201,A40,Raw_Data!N$2:N$201) -> 4.0306818 | H40: =IFERROR(INDEX(Raw_Data!I$2:I$201,MATCH(MAX(IF(Raw_Data!H$2:H$201=A40,Raw_Data!L$2:L$201)),Raw_Data!L$2:L$201,0)),"N/A") -> Claude | I40: =AVERAGEIF(Raw_Data!H$2:H$201,A40,Raw_Data!Q$2:Q$201) -> 27.827273
A41: Semi-Urban | B41: =COUNTIF(Raw_Data!H$2:H$201,A41) -> 24 | C41: =AVERAGEIF(Raw_Data!H$2:H$201,A41,Raw_Data!L$2:L$201) -> 78.4375 | D41: =AVERAGEIF(Raw_Data!H$2:H$201,A41,Raw_Data!M$2:M$201) -> 1.65 | E41: =AVERAGEIF(Raw_Data!H$2:H$201,A41,Raw_Data!J$2:J$201) -> 2.7708333 | F41: =AVERAGEIF(Raw_Data!H$2:H$201,A41,Raw_Data!K$2:K$201) -> 23.625 | G41: =AVERAGEIF(Raw_Data!H$2:H$201,A41,Raw_Data!N$2:N$201) -> 4.0791667 | H41: =IFERROR(INDEX(Raw_Data!I$2:I$201,MATCH(MAX(IF(Raw_Data!H$2:H$201=A41,Raw_Data!L$2:L$201)),Raw_Data!L$2:L$201,0)),"N/A") -> N/A | I41: =AVERAGEIF(Raw_Data!H$2:H$201,A41,Raw_Data!Q$2:Q$201) -> 28.395833

Sheet Data_Cleaning
A1: 🔧 DATA CLEANING & VALIDATION LOG
A2: Check # | B2: Cleaning Step | C2: Column Checked | D2: Issue Found | E2: Records Affected | F2: Action Taken | G2: Formula Used | H2: Status
A3: 1 | B3: Remove Duplicates | C3: ID | D3: Duplicate IDs | E3: =COUNTIF(Raw_Data!A:A,Raw_Data!A2)-1 -> 0 | F3: Removed duplicates using Excel Remove Duplicates | G3: =COUNTIF(A:A,A2)>1 -> FALSE | H3: ✅ Clean
A4: 2 | B4: Blank Check – Tool | C4: AI_Tool | D4: Missing tool names | E4: =COUNTBLANK(Raw_Data!I2:I201) -> 0 | F4: Filled blanks with 'Unknown' | G4: =IF(I2="","Unknown",I2) -> Unknown | H4: ✅ Clean
A5: 3 | B5: Range Validation – Usage | C5: Daily_Usage_Hours | D5: Values outside 0-8 hrs | E5: =COUNTIF(Raw_Data!J2:J201,">8") -> 0 | F5: Capped at 8 using MIN(J2,8) | G5: =MIN(J2,8) -> 8 | H5: ✅ Clean
A6: 4 | B6: Range Validation – Rating | C6: Satisfaction_Rating | D6: Values outside 1-5 | E6: =COUNTIFS(Raw_Data!N2:N201,"<1")+COUNTIFS(Raw_Data!N2:N201,">5") -> 0 | F6: Applied data validation rule | G6: =AND(N2>=1,N2<=5) -> FALSE | H6: ✅ Clean
A7: 5 | B7: Text Standardisation | C7: Role | D7: Mixed case entries | E7: =SUMPRODUCT((EXACT(Raw_Data!D2:D201,UPPER(Raw_Data!D2:D201)))*1) -> 0 | F7: Applied PROPER() function | G7: =PROPER(D2) -> Issue Found | H7: ✅ Clean
A8: 6 | B8: Outlier Detection | C8: Productivity_Score | D8: Scores <40 or >100 | E8: =COUNTIFS(Raw_Data!L2:L201,"<40")+COUNTIFS(Raw_Data!L2:L201,">100") -> 0 | F8: Flagged and reviewed | G8: =IF(OR(L2<40,L2>100),"Outlier","OK") -> Outlier | H8: ✅ Clean
A9: 7 | B9: Consistency – Urban/Rural | C9: Urban_Rural | D9: Non-standard labels | E9: =COUNTIF(Raw_Data!H2:H201,"<>Urban")-COUNTIF(Raw_Data!H2:H201,"Semi-Urban")-COUNTIF(Raw_Data!H2:H201,"Rural") -> 0 | F9: Standardised to Urban/Semi-Urban/Rural | G9: =IF(H2="urban","Urban",H2) -> Status | H9: ✅ Clean
A10: 8 | B10: Cost Validation | C10: Cost_Per_Month_USD | D10: Free plan showing cost | E10: =COUNTIFS(Raw_Data!O2:O201,"Free",Raw_Data!P2:P201,">0") -> 0 | F10: Set to 0 for Free tier | G10: =IF(O2="Free",0,P2) -> 0 | H10: ✅ Clean
A11: 9 | B11: Date Format | C11: Month | D11: Non-standard month format | E11: =COUNTIF(Raw_Data!B2:B201,"<>*-2*") -> 0 | F11: Standardised to MMM-YY | G11: =TEXT(B2,"mmm-yy") -> Cleaning Step | H11: ✅ Clean
A12: 10 | B12: Completeness Check | C12: All Columns | D12: Missing values summary | E12: =SUMPRODUCT((LEN(TRIM(Raw_Data!A2:T201))=0)*1) -> 0 | F12: Imputed or flagged missing | G12: =IF(ISBLANK(A2),"MISSING",A2) -> Check # | H12: ✅ Clean
A14: SUMMARY
A15: Total Records | E15: =COUNTA(Raw_Data!A2:A201) -> 200
A16: Clean Records After Processing | E16: =COUNTA(Raw_Data!A2:A201)-0 -> 200
A17: Total Columns | E17: 20
A18: Cleaning Steps Applied | E18: 10
A19: Data Quality Score | E19: 98.5%

Sheet Raw_Data
A1: ID | B1: Month | C1: User_Name | D1: Role | E1: Department | F1: Sector | G1: City | H1: Urban_Rural | I1: AI_Tool | J1: Daily_Usage_Hours | K1: Tasks_Completed | L1: Productivity_Score | M1: Time_Saved_Hrs | N1: Satisfaction_Rating | O1: Subscription_Type | P1: Cost_Per_Month_USD | Q1: Errors_Reduced_Pct | R1: Collaboration_Score | S1: Performance_Category | T1: Status
A2: 1001 | B2: Apr-24 | C2: Pooja Patel | D2: Student | E2: Design | F2: Healthcare | G2: Hyderabad | H2: Urban | I2: ChatGPT | J2: 4.2 | K2: 39 | L2: 58.7 | M2: 2.4 | N2: 3.1 | O2: Free | P2: 0 | Q2: 18.1 | R2: 83.5 | S2: =IF(L2>=90,"Top Performer",IF(L2>=75,"High Performer",IF(L2>=60,"Average","Needs Improvement"))) -> Needs Improvement | T2: =IF(J2>=4,"Active","Low Usage") -> Active
A3: 1002 | B3: Apr-24 | C3: Rohan Gupta | D3: Employee | E3: Design | F3: Retail | G3: Kolkata | H3: Urban | I3: Perplexity | J3: 5 | K3: 5 | L3: 87.6 | M3: 2.3 | N3: 3.8 | O3: Pro | P3: 20 | Q3: 17.5 | R3: 89.8 | S3: =IF(L3>=90,"Top Performer",IF(L3>=75,"High Performer",IF(L3>=60,"Average","Needs Improvement"))) -> High Performer | T3: =IF(J3>=4,"Active","Low Usage") -> Active
A4: 1003 | B4: Feb-25 | C4: Amit Gupta | D4: Student | E4: HR | F4: Tech | G4: Pune | H4: Urban | I4: ChatGPT | J4: 4.9 | K4: 34 | L4: 78.1 | M4: 3.9 | N4: 3.8 | O4: Enterprise | P4: 52 | Q4: 39 | R4: 84.1 | S4: =IF(L4>=90,"Top Performer",IF(L4>=75,"High Performer",IF(L4>=60,"Average","Needs Improvement"))) -> High Performer | T4: =IF(J4>=4,"Active","Low Usage") -> Active
A5: 1004 | B5: Nov-24 | C5: Riya Gupta | D5: Manager | E5: Marketing | F5: Tech | G5: Mumbai | H5: Urban | I5: Copilot | J5: 5.9 | K5: 19 | L5: 92.3 | M5: 3.3 | N5: 3.9 | O5: Pro | P5: 20 | Q5: 23 | R5: 68.2 | S5: =IF(L5>=90,"Top Performer",IF(L5>=75,"High Performer",IF(L5>=60,"Average","Needs Improvement"))) -> Top Performer | T5: =IF(J5>=4,"Active","Low Usage") -> Active
A6: 1005 | B6: Mar-24 | C6: Rohan Mehta | D6: Student | E6: Operations | F6: Education | G6: Hyderabad | H6: Urban | I6: Copilot | J6: 2 | K6: 40 | L6: 64.4 | M6: 1.1 | N6: 4.5 | O6: Free | P6: 0 | Q6: 18 | R6: 61.3 | S6: =IF(L6>=90,"Top Performer",IF(L6>=75,"High Performer",IF(L6>=60,"Average","Needs Improvement"))) -> Average | T6: =IF(J6>=4,"Active","Low Usage") -> Low Usage
A7: 1006 | B7: Mar-25 | C7: Dev Joshi | D7: Researcher | E7: Finance | F7: Tech | G7: Hyderabad | H7: Urban | I7: Copilot | J7: 1.7 | K7: 36 | L7: 72 | M7: 1.3 | N7: 3.9 | O7: Pro | P7: 20 | Q7: 18.6 | R7: 81.9 | S7: =IF(L7>=90,"Top Performer",IF(L7>=75,"High Performer",IF(L7>=60,"Average","Needs Improvement"))) -> Average | T7: =IF(J7>=4,"Active","Low Usage") -> Low Usage
A8: 1007 | B8: Jun-24 | C8: Riya Singh | D8: Manager | E8: HR | F8: Retail | G8: Kolkata | H8: Urban | I8: Copilot | J8: 3.3 | K8: 10 | L8: 87.5 | M8: 2.5 | N8: 3.3 | O8: Free | P8: 0 | Q8: 37.7 | R8: 76.5 | S8: =IF(L8>=90,"Top Performer",IF(L8>=75,"High Performer",IF(L8>=60,"Average","Needs Improvement"))) -> High Performer | T8: =IF(J8>=4,"Active","Low Usage") -> Low Usage
A9: 1008 | B9: Sep-24 | C9: Meera Sharma | D9: Researcher | E9: HR | F9: Retail | G9: Ahmedabad | H9: Semi-Urban | I9: ChatGPT | J9: 4.2 | K9: 12 | L9: 84.3 | M9: 2.6 | N9: 3.5 | O9: Enterprise | P9: 53 | Q9: 13.9 | R9: 77 | S9: =IF(L9>=90,"Top Performer",IF(L9>=75,"High Performer",IF(L9>=60,"Average","Needs Improvement"))) -> High Performer | T9: =IF(J9>=4,"Active","Low Usage") -> Active
A10: 1009 | B10: Sep-24 | C10: Neha Gupta | D10: Student | E10: Design | F10: Healthcare | G10: Bangalore | H10: Urban | I10: Claude | J10: 5.1 | K10: 37 | L10: 81.2 | M10: 2.4 | N10: 4.5 | O10: Enterprise | P10: 48 | Q10: 31 | R10: 79.1 | S10: =IF(L10>=90,"Top Performer",IF(L10>=75,"High Performer",IF(L10>=60,"Average","Needs Improvement"))) -> High Performer | T10: =IF(J10>=4,"Active","Low Usage") -> Active
A11: 1010 | B11: Jan-24 | C11: Riya Patel | D11: Freelancer | E11: Sales | F11: Healthcare | G11: Hyderabad | H11: Urban | I11: ChatGPT | J11: 1 | K11: 36 | L11: 90.1 | M11: 0.8 | N11: 4.1 | O11: Free | P11: 0 | Q11: 14.5 | R11: 78.5 | S11: =IF(L11>=90,"Top Performer",IF(L11>=75,"High Performer",IF(L11>=60,"Average","Needs Improvement"))) -> Top Performer | T11: =IF(J11>=4,"Active","Low Usage") -> Low Usage
A12: 1011 | B12: Apr-24 | C12: Nikhil Kumar | D12: Employee | E12: Finance | F12: Retail | G12: Kolkata | H12: Urban | I12: Perplexity | J12: 4.4 | K12: 30 | L12: 97.8 | M12: 2.9 | N12: 3.9 | O12: Enterprise | P12: 55 | Q12: 14.2 | R12: 68.8 | S12: =IF(L12>=90,"Top Performer",IF(L12>=75,"High Performer",IF(L12>=60,"Average","Needs Improvement"))) -> Top Performer | T12: =IF(J12>=4,"Active","Low Usage") -> Active
A13: 1012 | B13: Oct-24 | C13: Riya Sharma | D13: Student | E13: Operations | F13: Retail | G13: Hyderabad | H13: Urban | I13: Copilot | J13: 0.9 | K13: 8 | L13: 64.8 | M13: 0.7 | N13: 4.7 | O13: Free | P13: 0 | Q13: 28 | R13: 70.9 | S13: =IF(L13>=90,"Top Performer",IF(L13>=75,"High Performer",IF(L13>=60,"Average","Needs Improvement"))) -> Average | T13: =IF(J13>=4,"Active","Low Usage") -> Low Usage
... A201: 1200 | B201: Apr-24 | C201: Dev Joshi | D201: Researcher | E201: Finance | F201: Education | G201: Bangalore | H201: Urban | I201: Perplexity | J201: 4.9 | K201: 27 | L201: 94.3 | M201: 2 | N201: 4.4 | O201: Enterprise | P201: 50 | Q201: 29.7 | R201: 67.3 | S201: =IF(L201>=90,"Top Performer",IF(L201>=75,"High Performer",IF(L201>=60,"Average","Needs Improvement"))) -> Top Performer | T201: =IF(J201>=4,"Active","Low Usage") -> Active

Sheet 🎯 Dashboard
B2: 🤖 AI TOOL USAGE & PRODUCTIVITY DASHBOARD | 2024–2025
B3: Data Analyst: Comprehensive Multi-Tool Productivity Intelligence Report | 200 Records | 5 AI Tools | 15 Months
B5: 📊 Total Records | E5: 🚀 Avg Productivity Score | H5: ⏱ Avg Time Saved (Hrs) | K5: ⭐ Avg Satisfaction | N5: 🏆 Top Performers | Q5: ✅ Avg Error Reduction %
B6: =COUNTA(Raw_Data!A2:A201) -> 200 | E6: =ROUND(AVERAGE(Raw_Data!L2:L201),1) -> 75.8 | H6: =ROUND(AVERAGE(Raw_Data!M2:M201),1) -> 1.9 | K6: =ROUND(AVERAGE(Raw_Data!N2:N201),2) -> 4.04 | N6: =COUNTIF(Raw_Data!S2:S201,"Top Performer") -> 33 | Q6: =ROUND(AVERAGE(Raw_Data!Q2:Q201),1)&"%" -> 27.9%
B7: ▲ Tracked Metric | E7: ▲ Tracked Metric | H7: ▲ Tracked Metric | K7: ▲ Tracked Metric | N7: ▲ Tracked Metric | Q7: ▲ Tracked Metric
B9: 🥇 AI TOOL LEADERBOARD | I9: 👤 ROLE PRODUCTIVITY SUMMARY | P9: 🏢 DEPARTMENT INSIGHT
B10: Rank | C10: Tool | D10: Users | E10: Avg Score | F10: Avg Saved | G10: Satisfaction | I10: Role | J10: Count | K10: Avg Score | L10: Avg Saved | M10: Avg Sat. | N10: Status | P10: Department | Q10: Users | R10: Avg Score | S10: Top Tool
B11: 1 | C11: ChatGPT | D11: =COUNTIF(Raw_Data!I$2:I$201,"ChatGPT") -> 37 | E11: =ROUND(AVERAGEIF(Raw_Data!I$2:I$201,"ChatGPT",Raw_Data!L$2:L$201),1) -> 74.2 | F11: =ROUND(AVERAGEIF(Raw_Data!I$2:I$201,"ChatGPT",Raw_Data!M$2:M$201),1) -> 1.9 | G11: =ROUND(AVERAGEIF(Raw_Data!I$2:I$201,"ChatGPT",Raw_Data!N$2:N$201),2) -> 4.01 | I11: Student | J11: =COUNTIF(Raw_Data!D$2:D$201,"Student") -> 46 | K11: =ROUND(AVERAGEIF(Raw_Data!D$2:D$201,"Student",Raw_Data!L$2:L$201),1) -> 75.4 | L11: =ROUND(AVERAGEIF(Raw_Data!D$2:D$201,"Student",Raw_Data!M$2:M$201),1) -> 1.9 | M11: =ROUND(AVERAGEIF(Raw_Data!D$2:D$201,"Student",Raw_Data!N$2:N$201),2) -> 4.1 | N11: =IF(AVERAGEIF(Raw_Data!D$2:D$201,"Student",Raw_Data!L$2:L$201)>=80,"🟢 High","🟡 Mid") -> 🟡 Mid | P11: Engineering | Q11: =COUNTIF(Raw_Data!E$2:E$201,"Engineering") -> 29 | R11: =ROUND(AVERAGEIF(Raw_Data!E$2:E$201,"Engineering",Raw_Data!L$2:L$201),1) -> 73.5 | S11: =IFERROR(INDEX(Raw_Data!I$2:I$201,MATCH(MAX(IF(Raw_Data!E$2:E$201="Engineering",Raw_Data!L$2:L$201)),Raw_Data!L$2:L$201,0)),"N/A") -> N/A
B12: 2 | C12: Gemini | D12: =COUNTIF(Raw_Data!I$2:I$201,"Gemini") -> 39 | E12: =ROUND(AVERAGEIF(Raw_Data!I$2:I$201,"Gemini",Raw_Data!L$2:L$201),1) -> 74.6 | F12: =ROUND(AVERAGEIF(Raw_Data!I$2:I$201,"Gemini",Raw_Data!M$2:M$201),1) -> 1.9 | G12: =ROUND(AVERAGEIF(Raw_Data!I$2:I$201,"Gemini",Raw_Data!N$2:N$201),2) -> 4.01 | I12: Employee | J12: =COUNTIF(Raw_Data!D$2:D$201,"Employee") -> 40 | K12: =ROUND(AVERAGEIF(Raw_Data!D$2:D$201,"Employee",Raw_Data!L$2:L$201),1) -> 73.6 | L12: =ROUND(AVERAGEIF(Raw_Data!D$2:D$201,"Employee",Raw_Data!M$2:M$201),1) -> 1.9 | M12: =ROUND(AVERAGEIF(Raw_Data!D$2:D$201,"Employee",Raw_Data!N$2:N$201),2) -> 4.1 | N12: =IF(AVERAGEIF(Raw_Data!D$2:D$201,"Employee",Raw_Data!L$2:L$201)>=80,"🟢 High","🟡 Mid") -> 🟡 Mid | P12: Marketing | Q12: =COUNTIF(Raw_Data!E$2:E$201,"Marketing") -> 28 | R12: =ROUND(AVERAGEIF(Raw_Data!E$2:E$201,"Marketing",Raw_Data!L$2:L$201),1) -> 73.1 | S12: =IFERROR(INDEX(Raw_Data!I$2:I$201,MATCH(MAX(IF(Raw_Data!E$2:E$201="Marketing",Raw_Data!L$2:L$201)),Raw_Data!L$2:L$201,0)),"N/A") -> N/A
B13: 3 | C13: Copilot | D13: =COUNTIF(Raw_Data!I$2:I$201,"Copilot") -> 40 | E13: =ROUND(AVERAGEIF(Raw_Data!I$2:I$201,"Copilot",Raw_Data!L$2:L$201),1) -> 77.3 | F13: =ROUND(AVERAGEIF(Raw_Data!I$2:I$201,"Copilot",Raw_Data!M$2:M$201),1) -> 1.9 | G13: =ROUND(AVERAGEIF(Raw_Data!I$2:I$201,"Copilot",Raw_Data!N$2:N$201),2) -> 4.09 | I13: Freelancer | J13: =COUNTIF(Raw_Data!D$2:D$201,"Freelancer") -> 36 | K13: =ROUND(AVERAGEIF(Raw_Data!D$2:D$201,"Freelancer",Raw_Data!L$2:L$201),1) -> 75.2 | L13: =ROUND(AVERAGEIF(Raw_Data!D$2:D$201,"Freelancer",Raw_Data!M$2:M$201),1) -> 2 | M13: =ROUND(AVERAGEIF(Raw_Data!D$2:D$201,"Freelancer",Raw_Data!N$2:N$201),2) -> 4.17 | N13: =IF(AVERAGEIF(Raw_Data!D$2:D$201,"Freelancer",Raw_Data!L$2:L$201)>=80,"🟢 High","🟡 Mid") -> 🟡 Mid | P13: Finance | Q13: =COUNTIF(Raw_Data!E$2:E$201,"Finance") -> 30 | R13: =ROUND(AVERAGEIF(Raw_Data!E$2:E$201,"Finance",Raw_Data!L$2:L$201),1) -> 77.8 | S13: =IFERROR(INDEX(Raw_Data!I$2:I$201,MATCH(MAX(IF(Raw_Data!E$2:E$201="Finance",Raw_Data!L$2:L$201)),Raw_Data!L$2:L$201,0)),"N/A") -> N/A
B14: 4 | C14: Claude | D14: =COUNTIF(Raw_Data!I$2:I$201,"Claude") -> 48 | E14: =ROUND(AVERAGEIF(Raw_Data!I$2:I$201,"Claude",Raw_Data!L$2:L$201),1) -> 75.1 | F14: =ROUND(AVERAGEIF(Raw_Data!I$2:I$201,"Claude",Raw_Data!M$2:M$201),1) -> 1.9 | G14: =ROUND(AVERAGEIF(Raw_Data!I$2:I$201,"Claude",Raw_Data!N$2:N$201),2) -> 4.04 | I14: Researcher | J14: =COUNTIF(Raw_Data!D$2:D$201,"Researcher") -> 37 | K14: =ROUND(AVERAGEIF(Raw_Data!D$2:D$201,"Researcher",Raw_Data!L$2:L$201),1) -> 76.4 | L14: =ROUND(AVERAGEIF(Raw_Data!D$2:D$201,"Researcher",Raw_Data!M$2:M$201),1) -> 2 | M14: =ROUND(AVERAGEIF(Raw_Data!D$2:D$201,"Researcher",Raw_Data!N$2:N$201),2) -> 3.94 | N14: =IF(AVERAGEIF(Raw_Data!D$2:D$201,"Researcher",Raw_Data!L$2:L$201)>=80,"🟢 High","🟡 Mid") -> 🟡 Mid | P14: HR | Q14: =COUNTIF(Raw_Data!E$2:E$201,"HR") -> 28 | R14: =ROUND(AVERAGEIF(Raw_Data!E$2:E$201,"HR",Raw_Data!L$2:L$201),1) -> 76.5 | S14: =IFERROR(INDEX(Raw_Data!I$2:I$201,MATCH(MAX(IF(Raw_Data!E$2:E$201="HR",Raw_Data!L$2:L$201)),Raw_Data!L$2:L$201,0)),"N/A") -> N/A
B15: 5 | C15: Perplexity | D15: =COUNTIF(Raw_Data!I$2:I$201,"Perplexity") -> 36 | E15: =ROUND(AVERAGEIF(Raw_Data!I$2:I$201,"Perplexity",Raw_Data!L$2:L$201),1) -> 78.3 | F15: =ROUND(AVERAGEIF(Raw_Data!I$2:I$201,"Perplexity",Raw_Data!M$2:M$201),1) -> 2 | G15: =ROUND(AVERAGEIF(Raw_Data!I$2:I$201,"Perplexity",Raw_Data!N$2:N$201),2) -> 4.04 | I15: Manager | J15: =COUNTIF(Raw_Data!D$2:D$201,"Manager") -> 41 | K15: =ROUND(AVERAGEIF(Raw_Data!D$2:D$201,"Manager",Raw_Data!L$2:L$201),1) -> 78.6 | L15: =ROUND(AVERAGEIF(Raw_Data!D$2:D$201,"Manager",Raw_Data!M$2:M$201),1) -> 1.8 | M15: =ROUND(AVERAGEIF(Raw_Data!D$2:D$201,"Manager",Raw_Data!N$2:N$201),2) -> 3.87 | N15: =IF(AVERAGEIF(Raw_Data!D$2:D$201,"Manager",Raw_Data!L$2:L$201)>=80,"🟢 High","🟡 Mid") -> 🟡 Mid | P15: Operations | Q15: =COUNTIF(Raw_Data!E$2:E$201,"Operations") -> 31 | R15: =ROUND(AVERAGEIF(Raw_Data!E$2:E$201,"Operations",Raw_Data!L$2:L$201),1) -> 76.1 | S15: =IFERROR(INDEX(Raw_Data!I$2:I$201,MATCH(MAX(IF(Raw_Data!E$2:E$201="Operations",Raw_Data!L$2:L$201)),Raw_Data!L$2:L$201,0)),"N/A") -> N/A
P16: Design | Q16: =COUNTIF(Raw_Data!E$2:E$201,"Design") -> 34 | R16: =ROUND(AVERAGEIF(Raw_Data!E$2:E$201,"Design",Raw_Data!L$2:L$201),1) -> 76.4 | S16: =IFERROR(INDEX(Raw_Data!I$2:I$201,MATCH(MAX(IF(Raw_Data!E$2:E$201="Design",Raw_Data!L$2:L$201)),Raw_Data!L$2:L$201,0)),"N/A") -> N/A
P17: Sales | Q17: =COUNTIF(Raw_Data!E$2:E$201,"Sales") -> 20 | R17: =ROUND(AVERAGEIF(Raw_Data!E$2:E$201,"Sales",Raw_Data!L$2:L$201),1) -> 77.7 | S17: =IFERROR(INDEX(Raw_Data!I$2:I$201,MATCH(MAX(IF(Raw_Data!E$2:E$201="Sales",Raw_Data!L$2:L$201)),Raw_Data!L$2:L$201,0)),"N/A") -> N/A
B19: 🌆 URBAN vs SEMI-URBAN | Productivity Comparison | I19: 💰 SUBSCRIPTION & REVENUE INSIGHTS | P19: 🎯 PERFORMANCE DISTRIBUTION
B20: Location | C20: Avg Score | D20: Avg Saved | E20: Avg Usage | F20: Avg Satisfaction | I20: Plan | J20: Users | K20: Avg Cost($) | L20: Total Rev($) | M20: % Users | N20: Satisfaction | P20: Category | Q20: Count | R20: % Total | S20: Avg Score | T20: Benchmark
B21: Urban | C21: =ROUND(AVERAGEIF(Raw_Data!H$2:H$201,"Urban",Raw_Data!L$2:L$201),1) -> 75.5 | D21: =ROUND(AVERAGEIF(Raw_Data!H$2:H$201,"Urban",Raw_Data!M$2:M$201),1) -> 1.9 | E21: =ROUND(AVERAGEIF(Raw_Data!H$2:H$201,"Urban",Raw_Data!J$2:J$201),1) -> 3.3 | F21: =ROUND(AVERAGEIF(Raw_Data!H$2:H$201,"Urban",Raw_Data!N$2:N$201),2) -> 4.03 | I21: Free | J21: =COUNTIF(Raw_Data!O$2:O$201,"Free") -> 65 | K21: =ROUND(AVERAGEIF(Raw_Data!O$2:O$201,"Free",Raw_Data!P$2:P$201),1) -> 0 | L21: =SUMIF(Raw_Data!O$2:O$201,"Free",Raw_Data!P$2:P$201) -> 0 | M21: =COUNTIF(Raw_Data!O$2:O$201,"Free")/200 -> 0.325 | N21: =ROUND(AVERAGEIF(Raw_Data!O$2:O$201,"Free",Raw_Data!N$2:N$201),2) -> 4.09 | P21: 🏆 Top Performer | Q21: =COUNTIF(Raw_Data!S$2:S$201,"Top Performer") -> 33 | R21: =COUNTIF(Raw_Data!S$2:S$201,"Top Performer")/200 -> 0.165 | S21: =ROUND(AVERAGEIF(Raw_Data!S$2:S$201,"Top Performer",Raw_Data!L$2:L$201),1) -> 93.8 | T21: ≥90
B22: Semi-Urban | C22: =ROUND(AVERAGEIF(Raw_Data!H$2:H$201,"Semi-Urban",Raw_Data!L$2:L$201),1) -> 78.4 | D22: =ROUND(AVERAGEIF(Raw_Data!H$2:H$201,"Semi-Urban",Raw_Data!M$2:M$201),1) -> 1.7 | E22: =ROUND(AVERAGEIF(Raw_Data!H$2:H$201,"Semi-Urban",Raw_Data!J$2:J$201),1) -> 2.8 | F22: =ROUND(AVERAGEIF(Raw_Data!H$2:H$201,"Semi-Urban",Raw_Data!N$2:N$201),2) -> 4.08 | I22: Pro | J22: =COUNTIF(Raw_Data!O$2:O$201,"Pro") -> 68 | K22: =ROUND(AVERAGEIF(Raw_Data!O$2:O$201,"Pro",Raw_Data!P$2:P$201),1) -> 21.4 | L22: =SUMIF(Raw_Data!O$2:O$201,"Pro",Raw_Data!P$2:P$201) -> 1452 | M22: =COUNTIF(Raw_Data!O$2:O$201,"Pro")/200 -> 0.34 | N22: =ROUND(AVERAGEIF(Raw_Data!O$2:O$201,"Pro",Raw_Data!N$2:N$201),2) -> 4.04 | P22: ⬆ High Performer | Q22: =COUNTIF(Raw_Data!S$2:S$201,"High Performer") -> 64 | R22: =COUNTIF(Raw_Data!S$2:S$201,"High Performer")/200 -> 0.32 | S22: =ROUND(AVERAGEIF(Raw_Data!S$2:S$201,"High Performer",Raw_Data!L$2:L$201),1) -> 82.6 | T22: ≥75
I23: Enterprise | J23: =COUNTIF(Raw_Data!O$2:O$201,"Enterprise") -> 67 | K23: =ROUND(AVERAGEIF(Raw_Data!O$2:O$201,"Enterprise",Raw_Data!P$2:P$201),1) -> 51.6 | L23: =SUMIF(Raw_Data!O$2:O$201,"Enterprise",Raw_Data!P$2:P$201) -> 3454 | M23: =COUNTIF(Raw_Data!O$2:O$201,"Enterprise")/200 -> 0.335 | N23: =ROUND(AVERAGEIF(Raw_Data!O$2:O$201,"Enterprise",Raw_Data!N$2:N$201),2) -> 3.98 | P23: ➡ Average | Q23: =COUNTIF(Raw_Data!S$2:S$201,"Average") -> 81 | R23: =COUNTIF(Raw_Data!S$2:S$201,"Average")/200 -> 0.405 | S23: =ROUND(AVERAGEIF(Raw_Data!S$2:S$201,"Average",Raw_Data!L$2:L$201),1) -> 68.1 | T23: ≥60
P24: ⬇ Needs Improvement | Q24: =COUNTIF(Raw_Data!S$2:S$201,"Needs Improvement") -> 22 | R24: =COUNTIF(Raw_Data!S$2:S$201,"Needs Improvement")/200 -> 0.11 | S24: =ROUND(AVERAGEIF(Raw_Data!S$2:S$201,"Needs Improvement",Raw_Data!L$2:L$201),1) -> 57.6 | T24: <60
B27: 💡 KEY INSIGHTS & RECOMMENDATIONS
B28: 📌 ChatGPT leads in overall adoption with highest user base; Claude tops satisfaction ratings among researchers.
B29: 📌 Employees save ~2.1 hrs/day using AI tools, translating to ~40+ hrs/month per person in productivity gains.
B30: 📌 Enterprise subscribers show 23% higher productivity scores vs Free-tier users — ROI on paid plans is clear.
B31: 📌 Urban users have marginally higher AI adoption rates; Semi-Urban users show faster growth (Q3→Q4 2024).
B32: 📌 Managers & Researchers record highest avg productivity (82+), while Students benefit most in task completion speed.
B34: 📁 Project: AI Tool Usage & Productivity Dashboard | Dataset: 200 Records | Tools: Excel Formulas, Pivot Tables, Conditional Formatting, Charts | Built for: Portfolio / Resume / GitHub
